Watching for file changes with StatReloader
[20/Jun/2025 17:53:46] "POST /api/chat/token/ HTTP/1.1" 200 244
[20/Jun/2025 17:53:46] "GET /api/admin/dashboard/stats/ HTTP/1.1" 200 1405
[20/Jun/2025 17:53:46] "GET /api/admin/system/health/ HTTP/1.1" 200 332
[20/Jun/2025 17:53:46] "GET /api/admin/activity/feed/ HTTP/1.1" 200 2292
Internal Server Error: /api/admin/threads/
Traceback (most recent call last):
  File "/Users/rehanahmad/.pyenv/versions/3.11.9/lib/python3.11/site-packages/django/core/handlers/exception.py", line 47, in inner
    response = get_response(request)
               ^^^^^^^^^^^^^^^^^^^^^
  File "/Users/rehanahmad/.pyenv/versions/3.11.9/lib/python3.11/site-packages/django/core/handlers/base.py", line 181, in _get_response
    response = wrapped_callback(request, *callback_args, **callback_kwargs)
               ^^^^^^^^^^^^^^^^^^^^^^^^^^^^^^^^^^^^^^^^^^^^^^^^^^^^^^^^^^^^
  File "/Users/rehanahmad/.pyenv/versions/3.11.9/lib/python3.11/site-packages/django/views/decorators/csrf.py", line 54, in wrapped_view
    return view_func(*args, **kwargs)
           ^^^^^^^^^^^^^^^^^^^^^^^^^^
  File "/Users/rehanahmad/.pyenv/versions/3.11.9/lib/python3.11/site-packages/rest_framework/viewsets.py", line 125, in view
    return self.dispatch(request, *args, **kwargs)
           ^^^^^^^^^^^^^^^^^^^^^^^^^^^^^^^^^^^^^^^
  File "/Users/rehanahmad/.pyenv/versions/3.11.9/lib/python3.11/site-packages/rest_framework/views.py", line 509, in dispatch
    response = self.handle_exception(exc)
               ^^^^^^^^^^^^^^^^^^^^^^^^^^
  File "/Users/rehanahmad/.pyenv/versions/3.11.9/lib/python3.11/site-packages/rest_framework/views.py", line 469, in handle_exception
    self.raise_uncaught_exception(exc)
  File "/Users/rehanahmad/.pyenv/versions/3.11.9/lib/python3.11/site-packages/rest_framework/views.py", line 480, in raise_uncaught_exception
    raise exc
  File "/Users/rehanahmad/.pyenv/versions/3.11.9/lib/python3.11/site-packages/rest_framework/views.py", line 506, in dispatch
    response = handler(request, *args, **kwargs)
               ^^^^^^^^^^^^^^^^^^^^^^^^^^^^^^^^^
  File "/Users/rehanahmad/.pyenv/versions/3.11.9/lib/python3.11/site-packages/rest_framework/mixins.py", line 43, in list
    return self.get_paginated_response(serializer.data)
                                       ^^^^^^^^^^^^^^^
  File "/Users/rehanahmad/.pyenv/versions/3.11.9/lib/python3.11/site-packages/rest_framework/serializers.py", line 745, in data
    ret = super().data
          ^^^^^^^^^^^^
  File "/Users/rehanahmad/.pyenv/versions/3.11.9/lib/python3.11/site-packages/rest_framework/serializers.py", line 246, in data
    self._data = self.to_representation(self.instance)
                 ^^^^^^^^^^^^^^^^^^^^^^^^^^^^^^^^^^^^^
  File "/Users/rehanahmad/.pyenv/versions/3.11.9/lib/python3.11/site-packages/rest_framework/serializers.py", line 663, in to_representation
    return [
           ^
  File "/Users/rehanahmad/.pyenv/versions/3.11.9/lib/python3.11/site-packages/rest_framework/serializers.py", line 664, in <listcomp>
    self.child.to_representation(item) for item in iterable
    ^^^^^^^^^^^^^^^^^^^^^^^^^^^^^^^^^^
  File "/Users/rehanahmad/Desktop/CISCO/du-soc-chat-svc-main/chat_svc/chat/admin_api.py", line 56, in to_representation
    data = super().to_representation(instance)
           ^^^^^^^^^^^^^^^^^^^^^^^^^^^^^^^^^^^
  File "/Users/rehanahmad/.pyenv/versions/3.11.9/lib/python3.11/site-packages/rest_framework/serializers.py", line 500, in to_representation
    for field in fields:
  File "/Users/rehanahmad/.pyenv/versions/3.11.9/lib/python3.11/site-packages/rest_framework/serializers.py", line 361, in _readable_fields
    for field in self.fields.values():
                 ^^^^^^^^^^^
  File "/Users/rehanahmad/.pyenv/versions/3.11.9/lib/python3.11/site-packages/django/utils/functional.py", line 48, in __get__
    res = instance.__dict__[self.name] = self.func(instance)
                                         ^^^^^^^^^^^^^^^^^^^
  File "/Users/rehanahmad/.pyenv/versions/3.11.9/lib/python3.11/site-packages/rest_framework/serializers.py", line 349, in fields
    for key, value in self.get_fields().items():
                      ^^^^^^^^^^^^^^^^^
  File "/Users/rehanahmad/.pyenv/versions/3.11.9/lib/python3.11/site-packages/rest_framework/serializers.py", line 1053, in get_fields
    field_class, field_kwargs = self.build_field(
                                ^^^^^^^^^^^^^^^^^
  File "/Users/rehanahmad/.pyenv/versions/3.11.9/lib/python3.11/site-packages/rest_framework/serializers.py", line 1199, in build_field
    return self.build_unknown_field(field_name, model_class)
           ^^^^^^^^^^^^^^^^^^^^^^^^^^^^^^^^^^^^^^^^^^^^^^^^^
  File "/Users/rehanahmad/.pyenv/versions/3.11.9/lib/python3.11/site-packages/rest_framework/serializers.py", line 1317, in build_unknown_field
    raise ImproperlyConfigured(
django.core.exceptions.ImproperlyConfigured: Field name `tenant_name` is not valid for model `ChatThread`.
[20/Jun/2025 17:53:46] "GET /api/admin/threads/ HTTP/1.1" 500 155081
[20/Jun/2025 17:53:46] "GET /api/admin/users/ HTTP/1.1" 200 5633
[20/Jun/2025 17:53:46] "GET /api/admin/tenants/ HTTP/1.1" 200 316
[20/Jun/2025 17:53:46] "GET /api/admin/templates/ HTTP/1.1" 200 5183
[20/Jun/2025 17:53:54] "GET /api/admin/system/health/ HTTP/1.1" 200 332
[20/Jun/2025 17:53:54] "GET /api/admin/activity/feed/?limit=20 HTTP/1.1" 200 1099
[20/Jun/2025 17:53:54] "GET /api/admin/dashboard/stats/ HTTP/1.1" 200 1405
/Users/rehanahmad/Desktop/CISCO/du-soc-chat-svc-main/chat_svc/chat/admin_api.py changed, reloading.
Performing system checks...

System check identified no issues (0 silenced).
June 20, 2025 - 17:53:36
Django version 3.2, using settings 'chat_svc.settings'
Starting development server at http://127.0.0.1:8000/
Quit the server with CONTROL-C.
Watching for file changes with StatReloader
Exception in thread django-main-thread:
Traceback (most recent call last):
  File "/Users/rehanahmad/.pyenv/versions/3.11.9/lib/python3.11/threading.py", line 1045, in _bootstrap_inner
    self.run()
  File "/Users/rehanahmad/.pyenv/versions/3.11.9/lib/python3.11/threading.py", line 982, in run
    self._target(*self._args, **self._kwargs)
  File "/Users/rehanahmad/.pyenv/versions/3.11.9/lib/python3.11/site-packages/django/utils/autoreload.py", line 64, in wrapper
    fn(*args, **kwargs)
  File "/Users/rehanahmad/.pyenv/versions/3.11.9/lib/python3.11/site-packages/django/core/management/commands/runserver.py", line 118, in inner_run
    self.check(display_num_errors=True)
  File "/Users/rehanahmad/.pyenv/versions/3.11.9/lib/python3.11/site-packages/django/core/management/base.py", line 419, in check
    all_issues = checks.run_checks(
                 ^^^^^^^^^^^^^^^^^^
  File "/Users/rehanahmad/.pyenv/versions/3.11.9/lib/python3.11/site-packages/django/core/checks/registry.py", line 76, in run_checks
    new_errors = check(app_configs=app_configs, databases=databases)
                 ^^^^^^^^^^^^^^^^^^^^^^^^^^^^^^^^^^^^^^^^^^^^^^^^^^^
  File "/Users/rehanahmad/.pyenv/versions/3.11.9/lib/python3.11/site-packages/django/core/checks/urls.py", line 13, in check_url_config
    return check_resolver(resolver)
           ^^^^^^^^^^^^^^^^^^^^^^^^
  File "/Users/rehanahmad/.pyenv/versions/3.11.9/lib/python3.11/site-packages/django/core/checks/urls.py", line 23, in check_resolver
    return check_method()
           ^^^^^^^^^^^^^^
  File "/Users/rehanahmad/.pyenv/versions/3.11.9/lib/python3.11/site-packages/django/urls/resolvers.py", line 412, in check
    for pattern in self.url_patterns:
                   ^^^^^^^^^^^^^^^^^
  File "/Users/rehanahmad/.pyenv/versions/3.11.9/lib/python3.11/site-packages/django/utils/functional.py", line 48, in __get__
    res = instance.__dict__[self.name] = self.func(instance)
                                         ^^^^^^^^^^^^^^^^^^^
  File "/Users/rehanahmad/.pyenv/versions/3.11.9/lib/python3.11/site-packages/django/urls/resolvers.py", line 598, in url_patterns
    patterns = getattr(self.urlconf_module, "urlpatterns", self.urlconf_module)
                       ^^^^^^^^^^^^^^^^^^^
  File "/Users/rehanahmad/.pyenv/versions/3.11.9/lib/python3.11/site-packages/django/utils/functional.py", line 48, in __get__
    res = instance.__dict__[self.name] = self.func(instance)
                                         ^^^^^^^^^^^^^^^^^^^
  File "/Users/rehanahmad/.pyenv/versions/3.11.9/lib/python3.11/site-packages/django/urls/resolvers.py", line 591, in urlconf_module
    return import_module(self.urlconf_name)
           ^^^^^^^^^^^^^^^^^^^^^^^^^^^^^^^^
  File "/Users/rehanahmad/.pyenv/versions/3.11.9/lib/python3.11/importlib/__init__.py", line 126, in import_module
    return _bootstrap._gcd_import(name[level:], package, level)
           ^^^^^^^^^^^^^^^^^^^^^^^^^^^^^^^^^^^^^^^^^^^^^^^^^^^^
  File "<frozen importlib._bootstrap>", line 1204, in _gcd_import
  File "<frozen importlib._bootstrap>", line 1176, in _find_and_load
  File "<frozen importlib._bootstrap>", line 1147, in _find_and_load_unlocked
  File "<frozen importlib._bootstrap>", line 690, in _load_unlocked
  File "<frozen importlib._bootstrap_external>", line 940, in exec_module
  File "<frozen importlib._bootstrap>", line 241, in _call_with_frames_removed
  File "/Users/rehanahmad/Desktop/CISCO/du-soc-chat-svc-main/chat_svc/urls.py", line 21, in <module>
    path('api/admin/', include('chat_svc.chat.admin_urls')),  # Comprehensive admin API endpoints
                       ^^^^^^^^^^^^^^^^^^^^^^^^^^^^^^^^^^^
  File "/Users/rehanahmad/.pyenv/versions/3.11.9/lib/python3.11/site-packages/django/urls/conf.py", line 34, in include
    urlconf_module = import_module(urlconf_module)
                     ^^^^^^^^^^^^^^^^^^^^^^^^^^^^^
  File "/Users/rehanahmad/.pyenv/versions/3.11.9/lib/python3.11/importlib/__init__.py", line 126, in import_module
    return _bootstrap._gcd_import(name[level:], package, level)
           ^^^^^^^^^^^^^^^^^^^^^^^^^^^^^^^^^^^^^^^^^^^^^^^^^^^^
  File "<frozen importlib._bootstrap>", line 1204, in _gcd_import
  File "<frozen importlib._bootstrap>", line 1176, in _find_and_load
  File "<frozen importlib._bootstrap>", line 1147, in _find_and_load_unlocked
  File "<frozen importlib._bootstrap>", line 690, in _load_unlocked
  File "<frozen importlib._bootstrap_external>", line 940, in exec_module
  File "<frozen importlib._bootstrap>", line 241, in _call_with_frames_removed
  File "/Users/rehanahmad/Desktop/CISCO/du-soc-chat-svc-main/chat_svc/chat/admin_urls.py", line 10, in <module>
    from .admin_api import (
  File "/Users/rehanahmad/Desktop/CISCO/du-soc-chat-svc-main/chat_svc/chat/admin_api.py", line 45, in <module>
    class AdminThreadDetailSerializer(ChatThreadSerializer):
  File "/Users/rehanahmad/Desktop/CISCO/du-soc-chat-svc-main/chat_svc/chat/admin_api.py", line 49, in AdminThreadDetailSerializer
    tenant_name = serializers.SerializerMethodField()
                  ^^^^^^^^^^^
NameError: name 'serializers' is not defined
/Users/rehanahmad/Desktop/CISCO/du-soc-chat-svc-main/chat_svc/chat/admin_api.py changed, reloading.
Performing system checks...

Watching for file changes with StatReloader
/Users/rehanahmad/Desktop/CISCO/du-soc-chat-svc-main/chat_svc/chat/admin_api.py changed, reloading.
Performing system checks...

System check identified no issues (0 silenced).
June 20, 2025 - 17:54:08
Django version 3.2, using settings 'chat_svc.settings'
Starting development server at http://127.0.0.1:8000/
Quit the server with CONTROL-C.
Watching for file changes with StatReloader
[20/Jun/2025 17:54:24] "GET /api/admin/activity/feed/?limit=20 HTTP/1.1" 200 1099
[20/Jun/2025 17:54:24] "GET /api/admin/system/health/ HTTP/1.1" 200 332
[20/Jun/2025 17:54:24] "GET /api/admin/dashboard/stats/ HTTP/1.1" 200 1405
[20/Jun/2025 17:54:26] "GET /api/chat/admin/threads/ HTTP/1.1" 200 2590
[20/Jun/2025 17:54:27] "GET /api/chat/admin/threads/ HTTP/1.1" 200 2590
[20/Jun/2025 17:54:28] "GET /api/chat/admin/approve-user-action/ HTTP/1.1" 200 6388
[20/Jun/2025 17:54:28] "GET /api/chat/admin/approve-user-action/ HTTP/1.1" 200 6388
[20/Jun/2025 17:54:34] "GET /api/admin/system/health/ HTTP/1.1" 200 332
[20/Jun/2025 17:54:34] "GET /api/admin/activity/feed/?limit=20 HTTP/1.1" 200 1099
[20/Jun/2025 17:54:34] "GET /api/admin/system/health/ HTTP/1.1" 200 332
[20/Jun/2025 17:54:34] "GET /api/admin/activity/feed/?limit=20 HTTP/1.1" 200 1099
[20/Jun/2025 17:54:34] "GET /api/admin/dashboard/stats/ HTTP/1.1" 200 1405
[20/Jun/2025 17:54:35] "GET /api/admin/dashboard/stats/ HTTP/1.1" 200 1405
[20/Jun/2025 17:54:55] "GET /api/chat/admin/threads/ HTTP/1.1" 200 2590
[20/Jun/2025 17:54:55] "GET /api/chat/admin/threads/ HTTP/1.1" 200 2590
[20/Jun/2025 17:55:08] "POST /api/chat/token/ HTTP/1.1" 200 244
[20/Jun/2025 17:55:08] "GET /api/admin/dashboard/stats/ HTTP/1.1" 200 1405
[20/Jun/2025 17:55:08] "GET /api/admin/system/health/ HTTP/1.1" 200 332
[20/Jun/2025 17:55:09] "GET /api/admin/activity/feed/ HTTP/1.1" 200 2292
Internal Server Error: /api/admin/threads/
Traceback (most recent call last):
  File "/Users/rehanahmad/.pyenv/versions/3.11.9/lib/python3.11/site-packages/django/core/handlers/exception.py", line 47, in inner
    response = get_response(request)
               ^^^^^^^^^^^^^^^^^^^^^
  File "/Users/rehanahmad/.pyenv/versions/3.11.9/lib/python3.11/site-packages/django/core/handlers/base.py", line 181, in _get_response
    response = wrapped_callback(request, *callback_args, **callback_kwargs)
               ^^^^^^^^^^^^^^^^^^^^^^^^^^^^^^^^^^^^^^^^^^^^^^^^^^^^^^^^^^^^
  File "/Users/rehanahmad/.pyenv/versions/3.11.9/lib/python3.11/site-packages/django/views/decorators/csrf.py", line 54, in wrapped_view
    return view_func(*args, **kwargs)
           ^^^^^^^^^^^^^^^^^^^^^^^^^^
  File "/Users/rehanahmad/.pyenv/versions/3.11.9/lib/python3.11/site-packages/rest_framework/viewsets.py", line 125, in view
    return self.dispatch(request, *args, **kwargs)
           ^^^^^^^^^^^^^^^^^^^^^^^^^^^^^^^^^^^^^^^
  File "/Users/rehanahmad/.pyenv/versions/3.11.9/lib/python3.11/site-packages/rest_framework/views.py", line 509, in dispatch
    response = self.handle_exception(exc)
               ^^^^^^^^^^^^^^^^^^^^^^^^^^
  File "/Users/rehanahmad/.pyenv/versions/3.11.9/lib/python3.11/site-packages/rest_framework/views.py", line 469, in handle_exception
    self.raise_uncaught_exception(exc)
  File "/Users/rehanahmad/.pyenv/versions/3.11.9/lib/python3.11/site-packages/rest_framework/views.py", line 480, in raise_uncaught_exception
    raise exc
  File "/Users/rehanahmad/.pyenv/versions/3.11.9/lib/python3.11/site-packages/rest_framework/views.py", line 506, in dispatch
    response = handler(request, *args, **kwargs)
               ^^^^^^^^^^^^^^^^^^^^^^^^^^^^^^^^^
  File "/Users/rehanahmad/.pyenv/versions/3.11.9/lib/python3.11/site-packages/rest_framework/mixins.py", line 43, in list
    return self.get_paginated_response(serializer.data)
                                       ^^^^^^^^^^^^^^^
  File "/Users/rehanahmad/.pyenv/versions/3.11.9/lib/python3.11/site-packages/rest_framework/serializers.py", line 745, in data
    ret = super().data
          ^^^^^^^^^^^^
  File "/Users/rehanahmad/.pyenv/versions/3.11.9/lib/python3.11/site-packages/rest_framework/serializers.py", line 246, in data
    self._data = self.to_representation(self.instance)
                 ^^^^^^^^^^^^^^^^^^^^^^^^^^^^^^^^^^^^^
  File "/Users/rehanahmad/.pyenv/versions/3.11.9/lib/python3.11/site-packages/rest_framework/serializers.py", line 663, in to_representation
    return [
           ^
  File "/Users/rehanahmad/.pyenv/versions/3.11.9/lib/python3.11/site-packages/rest_framework/serializers.py", line 664, in <listcomp>
    self.child.to_representation(item) for item in iterable
    ^^^^^^^^^^^^^^^^^^^^^^^^^^^^^^^^^^
  File "/Users/rehanahmad/Desktop/CISCO/du-soc-chat-svc-main/chat_svc/chat/admin_api.py", line 69, in to_representation
    data = super().to_representation(instance)
           ^^^^^^^^^^^^^^^^^^^^^^^^^^^^^^^^^^^
  File "/Users/rehanahmad/.pyenv/versions/3.11.9/lib/python3.11/site-packages/rest_framework/serializers.py", line 515, in to_representation
    ret[field.field_name] = field.to_representation(attribute)
                            ^^^^^^^^^^^^^^^^^^^^^^^^^^^^^^^^^^
  File "/Users/rehanahmad/.pyenv/versions/3.11.9/lib/python3.11/site-packages/rest_framework/fields.py", line 1869, in to_representation
    method = getattr(self.parent, self.method_name)
             ^^^^^^^^^^^^^^^^^^^^^^^^^^^^^^^^^^^^^^
AttributeError: 'AdminThreadDetailSerializer' object has no attribute 'get_tenant_name'
[20/Jun/2025 17:55:09] "GET /api/admin/threads/ HTTP/1.1" 500 151247
[20/Jun/2025 17:55:09] "GET /api/admin/users/ HTTP/1.1" 200 5633
[20/Jun/2025 17:55:09] "GET /api/admin/tenants/ HTTP/1.1" 200 316
[20/Jun/2025 17:55:09] "GET /api/admin/templates/ HTTP/1.1" 200 5183
[20/Jun/2025 17:56:18] "GET /api/admin/system/health/ HTTP/1.1" 200 332
[20/Jun/2025 17:56:18] "GET /api/admin/activity/feed/?limit=20 HTTP/1.1" 200 1099
[20/Jun/2025 17:56:18] "GET /api/admin/system/health/ HTTP/1.1" 200 332
[20/Jun/2025 17:56:18] "GET /api/admin/activity/feed/?limit=20 HTTP/1.1" 200 1099
[20/Jun/2025 17:56:18] "GET /api/admin/dashboard/stats/ HTTP/1.1" 200 1405
[20/Jun/2025 17:56:18] "GET /api/admin/dashboard/stats/ HTTP/1.1" 200 1405
[20/Jun/2025 17:56:48] "GET /api/admin/system/health/ HTTP/1.1" 200 332
[20/Jun/2025 17:56:48] "GET /api/admin/activity/feed/?limit=20 HTTP/1.1" 200 1099
[20/Jun/2025 17:56:48] "GET /api/admin/dashboard/stats/ HTTP/1.1" 200 1405
[20/Jun/2025 17:57:02] "GET /api/chat/admin/threads/ HTTP/1.1" 200 2590
[20/Jun/2025 17:57:02] "GET /api/chat/admin/threads/ HTTP/1.1" 200 2590
[20/Jun/2025 17:57:03] "GET /api/chat/admin/approve-user-action/ HTTP/1.1" 200 6388
[20/Jun/2025 17:57:03] "GET /api/chat/admin/approve-user-action/ HTTP/1.1" 200 6388
[20/Jun/2025 17:57:47] "POST /api/chat/token/ HTTP/1.1" 200 252
[20/Jun/2025 17:57:47] "GET /api/chat/templates/ HTTP/1.1" 200 4397
[20/Jun/2025 17:57:47] "GET /api/chat/templates/ HTTP/1.1" 200 4397
[20/Jun/2025 17:57:47] "GET /api/chat/threads/ HTTP/1.1" 200 2590
[20/Jun/2025 17:57:47] "GET /api/chat/threads/ HTTP/1.1" 200 2590
[20/Jun/2025 17:57:48] "GET /api/chat/threads/1/ HTTP/1.1" 200 2588
Not Found: /ws/chat/1/
[20/Jun/2025 17:57:48] "GET /ws/chat/1/?token=eyJhbGciOiJIUzI1NiIsInR5cCI6IkpXVCJ9.eyJ1c2VyX2lkIjoyLCJ1c2VybmFtZSI6ImFtaW5hIiwidGVuYW50X2lkIjoxLCJ0ZW5hbnQiOiJBbHBoYSBDb3JwIiwiaXNfc3RhZmYiOmZhbHNlLCJleHAiOjE3NTA0NDU4NjcsImlhdCI6MTc1MDQ0MjI2N30.pRkxvg3AN2KZ2m74sMhg2Pi78US1hhcH3ToZwQLSZjc HTTP/1.1" 404 2721
[20/Jun/2025 17:57:48] "GET /api/chat/threads/1/ HTTP/1.1" 200 2588
Not Found: /ws/chat/1/
[20/Jun/2025 17:57:49] "GET /ws/chat/1/?token=eyJhbGciOiJIUzI1NiIsInR5cCI6IkpXVCJ9.eyJ1c2VyX2lkIjoyLCJ1c2VybmFtZSI6ImFtaW5hIiwidGVuYW50X2lkIjoxLCJ0ZW5hbnQiOiJBbHBoYSBDb3JwIiwiaXNfc3RhZmYiOmZhbHNlLCJleHAiOjE3NTA0NDU4NjcsImlhdCI6MTc1MDQ0MjI2N30.pRkxvg3AN2KZ2m74sMhg2Pi78US1hhcH3ToZwQLSZjc HTTP/1.1" 404 2721
Not Found: /ws/chat/1/
[20/Jun/2025 17:57:51] "GET /ws/chat/1/?token=eyJhbGciOiJIUzI1NiIsInR5cCI6IkpXVCJ9.eyJ1c2VyX2lkIjoyLCJ1c2VybmFtZSI6ImFtaW5hIiwidGVuYW50X2lkIjoxLCJ0ZW5hbnQiOiJBbHBoYSBDb3JwIiwiaXNfc3RhZmYiOmZhbHNlLCJleHAiOjE3NTA0NDU4NjcsImlhdCI6MTc1MDQ0MjI2N30.pRkxvg3AN2KZ2m74sMhg2Pi78US1hhcH3ToZwQLSZjc HTTP/1.1" 404 2721
Not Found: /ws/chat/1/
[20/Jun/2025 17:57:56] "GET /ws/chat/1/?token=eyJhbGciOiJIUzI1NiIsInR5cCI6IkpXVCJ9.eyJ1c2VyX2lkIjoyLCJ1c2VybmFtZSI6ImFtaW5hIiwidGVuYW50X2lkIjoxLCJ0ZW5hbnQiOiJBbHBoYSBDb3JwIiwiaXNfc3RhZmYiOmZhbHNlLCJleHAiOjE3NTA0NDU4NjcsImlhdCI6MTc1MDQ0MjI2N30.pRkxvg3AN2KZ2m74sMhg2Pi78US1hhcH3ToZwQLSZjc HTTP/1.1" 404 2721
Not Found: /ws/chat/1/
[20/Jun/2025 17:58:04] "GET /ws/chat/1/?token=eyJhbGciOiJIUzI1NiIsInR5cCI6IkpXVCJ9.eyJ1c2VyX2lkIjoyLCJ1c2VybmFtZSI6ImFtaW5hIiwidGVuYW50X2lkIjoxLCJ0ZW5hbnQiOiJBbHBoYSBDb3JwIiwiaXNfc3RhZmYiOmZhbHNlLCJleHAiOjE3NTA0NDU4NjcsImlhdCI6MTc1MDQ0MjI2N30.pRkxvg3AN2KZ2m74sMhg2Pi78US1hhcH3ToZwQLSZjc HTTP/1.1" 404 2721
[20/Jun/2025 17:59:29] "GET /admin/chat/structuredreply/ HTTP/1.1" 302 0
[20/Jun/2025 17:59:29] "GET /admin/login/?next=/admin/chat/structuredreply/ HTTP/1.1" 200 2256
Bad Request: /api/chat/token/
[20/Jun/2025 17:59:46] "POST /api/chat/token/ HTTP/1.1" 400 32
Bad Request: /api/chat/token/
[20/Jun/2025 17:59:47] "POST /api/chat/token/ HTTP/1.1" 400 32
Bad Request: /api/chat/token/
[20/Jun/2025 17:59:47] "POST /api/chat/token/ HTTP/1.1" 400 32
Bad Request: /api/chat/token/
[20/Jun/2025 17:59:48] "POST /api/chat/token/ HTTP/1.1" 400 32
Bad Request: /api/chat/token/
[20/Jun/2025 17:59:48] "POST /api/chat/token/ HTTP/1.1" 400 32
Bad Request: /api/chat/token/
[20/Jun/2025 17:59:49] "POST /api/chat/token/ HTTP/1.1" 400 32
Bad Request: /api/chat/token/
[20/Jun/2025 17:59:50] "POST /api/chat/token/ HTTP/1.1" 400 32
Bad Request: /api/chat/token/
[20/Jun/2025 17:59:51] "POST /api/chat/token/ HTTP/1.1" 400 32
[20/Jun/2025 18:52:00] "GET /admin/chat/structuredreply/ HTTP/1.1" 302 0
[20/Jun/2025 18:52:00] "GET /admin/login/?next=/admin/chat/structuredreply/ HTTP/1.1" 200 2256
/Users/rehanahmad/Desktop/CISCO/du-soc-chat-svc-main/chat_svc/urls.py changed, reloading.
Performing system checks...

System check identified no issues (0 silenced).
June 20, 2025 - 17:54:18
Django version 3.2, using settings 'chat_svc.settings'
Starting development server at http://127.0.0.1:8000/
Quit the server with CONTROL-C.
Watching for file changes with StatReloader
Exception in thread django-main-thread:
Traceback (most recent call last):
  File "/Users/rehanahmad/.pyenv/versions/3.11.9/lib/python3.11/logging/config.py", line 573, in configure
    handler = self.configure_handler(handlers[name])
              ^^^^^^^^^^^^^^^^^^^^^^^^^^^^^^^^^^^^^^
  File "/Users/rehanahmad/.pyenv/versions/3.11.9/lib/python3.11/logging/config.py", line 757, in configure_handler
    result = factory(**kwargs)
             ^^^^^^^^^^^^^^^^^
  File "/Users/rehanahmad/.pyenv/versions/3.11.9/lib/python3.11/logging/__init__.py", line 1181, in __init__
    StreamHandler.__init__(self, self._open())
                                 ^^^^^^^^^^^^
  File "/Users/rehanahmad/.pyenv/versions/3.11.9/lib/python3.11/logging/__init__.py", line 1213, in _open
    return open_func(self.baseFilename, self.mode,
           ^^^^^^^^^^^^^^^^^^^^^^^^^^^^^^^^^^^^^^^
FileNotFoundError: [Errno 2] No such file or directory: '/Users/rehanahmad/Desktop/CISCO/du-soc-chat-svc-main/logs/django.log'

The above exception was the direct cause of the following exception:

Traceback (most recent call last):
  File "/Users/rehanahmad/.pyenv/versions/3.11.9/lib/python3.11/threading.py", line 1045, in _bootstrap_inner
    self.run()
  File "/Users/rehanahmad/.pyenv/versions/3.11.9/lib/python3.11/threading.py", line 982, in run
    self._target(*self._args, **self._kwargs)
  File "/Users/rehanahmad/.pyenv/versions/3.11.9/lib/python3.11/site-packages/django/utils/autoreload.py", line 64, in wrapper
    fn(*args, **kwargs)
  File "/Users/rehanahmad/.pyenv/versions/3.11.9/lib/python3.11/site-packages/django/core/management/commands/runserver.py", line 110, in inner_run
    autoreload.raise_last_exception()
  File "/Users/rehanahmad/.pyenv/versions/3.11.9/lib/python3.11/site-packages/django/utils/autoreload.py", line 87, in raise_last_exception
    raise _exception[1]
  File "/Users/rehanahmad/.pyenv/versions/3.11.9/lib/python3.11/site-packages/django/core/management/__init__.py", line 375, in execute
    autoreload.check_errors(django.setup)()
  File "/Users/rehanahmad/.pyenv/versions/3.11.9/lib/python3.11/site-packages/django/utils/autoreload.py", line 64, in wrapper
    fn(*args, **kwargs)
  File "/Users/rehanahmad/.pyenv/versions/3.11.9/lib/python3.11/site-packages/django/__init__.py", line 19, in setup
    configure_logging(settings.LOGGING_CONFIG, settings.LOGGING)
  File "/Users/rehanahmad/.pyenv/versions/3.11.9/lib/python3.11/site-packages/django/utils/log.py", line 75, in configure_logging
    logging_config_func(logging_settings)
  File "/Users/rehanahmad/.pyenv/versions/3.11.9/lib/python3.11/logging/config.py", line 823, in dictConfig
    dictConfigClass(config).configure()
  File "/Users/rehanahmad/.pyenv/versions/3.11.9/lib/python3.11/logging/config.py", line 580, in configure
    raise ValueError('Unable to configure handler '
ValueError: Unable to configure handler 'file'
/Users/rehanahmad/Desktop/CISCO/du-soc-chat-svc-main/chat_svc/settings/base.py changed, reloading.
Watching for file changes with StatReloader
Exception in thread django-main-thread:
Traceback (most recent call last):
  File "/Users/rehanahmad/.pyenv/versions/3.11.9/lib/python3.11/logging/config.py", line 573, in configure
    handler = self.configure_handler(handlers[name])
              ^^^^^^^^^^^^^^^^^^^^^^^^^^^^^^^^^^^^^^
  File "/Users/rehanahmad/.pyenv/versions/3.11.9/lib/python3.11/logging/config.py", line 757, in configure_handler
    result = factory(**kwargs)
             ^^^^^^^^^^^^^^^^^
  File "/Users/rehanahmad/.pyenv/versions/3.11.9/lib/python3.11/logging/__init__.py", line 1181, in __init__
    StreamHandler.__init__(self, self._open())
                                 ^^^^^^^^^^^^
  File "/Users/rehanahmad/.pyenv/versions/3.11.9/lib/python3.11/logging/__init__.py", line 1213, in _open
    return open_func(self.baseFilename, self.mode,
           ^^^^^^^^^^^^^^^^^^^^^^^^^^^^^^^^^^^^^^^
FileNotFoundError: [Errno 2] No such file or directory: '/Users/rehanahmad/Desktop/CISCO/du-soc-chat-svc-main/logs/django.log'

The above exception was the direct cause of the following exception:

Traceback (most recent call last):
  File "/Users/rehanahmad/.pyenv/versions/3.11.9/lib/python3.11/threading.py", line 1045, in _bootstrap_inner
    self.run()
  File "/Users/rehanahmad/.pyenv/versions/3.11.9/lib/python3.11/threading.py", line 982, in run
    self._target(*self._args, **self._kwargs)
  File "/Users/rehanahmad/.pyenv/versions/3.11.9/lib/python3.11/site-packages/django/utils/autoreload.py", line 64, in wrapper
    fn(*args, **kwargs)
  File "/Users/rehanahmad/.pyenv/versions/3.11.9/lib/python3.11/site-packages/django/core/management/commands/runserver.py", line 110, in inner_run
    autoreload.raise_last_exception()
  File "/Users/rehanahmad/.pyenv/versions/3.11.9/lib/python3.11/site-packages/django/utils/autoreload.py", line 87, in raise_last_exception
    raise _exception[1]
  File "/Users/rehanahmad/.pyenv/versions/3.11.9/lib/python3.11/site-packages/django/core/management/__init__.py", line 375, in execute
    autoreload.check_errors(django.setup)()
  File "/Users/rehanahmad/.pyenv/versions/3.11.9/lib/python3.11/site-packages/django/utils/autoreload.py", line 64, in wrapper
    fn(*args, **kwargs)
  File "/Users/rehanahmad/.pyenv/versions/3.11.9/lib/python3.11/site-packages/django/__init__.py", line 19, in setup
    configure_logging(settings.LOGGING_CONFIG, settings.LOGGING)
  File "/Users/rehanahmad/.pyenv/versions/3.11.9/lib/python3.11/site-packages/django/utils/log.py", line 75, in configure_logging
    logging_config_func(logging_settings)
  File "/Users/rehanahmad/.pyenv/versions/3.11.9/lib/python3.11/logging/config.py", line 823, in dictConfig
    dictConfigClass(config).configure()
  File "/Users/rehanahmad/.pyenv/versions/3.11.9/lib/python3.11/logging/config.py", line 580, in configure
    raise ValueError('Unable to configure handler '
ValueError: Unable to configure handler 'file'
/Users/rehanahmad/Desktop/CISCO/du-soc-chat-svc-main/chat_svc/settings/base.py changed, reloading.
Watching for file changes with StatReloader
Exception in thread django-main-thread:
Traceback (most recent call last):
  File "/Users/rehanahmad/.pyenv/versions/3.11.9/lib/python3.11/logging/config.py", line 573, in configure
    handler = self.configure_handler(handlers[name])
              ^^^^^^^^^^^^^^^^^^^^^^^^^^^^^^^^^^^^^^
  File "/Users/rehanahmad/.pyenv/versions/3.11.9/lib/python3.11/logging/config.py", line 757, in configure_handler
    result = factory(**kwargs)
             ^^^^^^^^^^^^^^^^^
  File "/Users/rehanahmad/.pyenv/versions/3.11.9/lib/python3.11/logging/__init__.py", line 1181, in __init__
    StreamHandler.__init__(self, self._open())
                                 ^^^^^^^^^^^^
  File "/Users/rehanahmad/.pyenv/versions/3.11.9/lib/python3.11/logging/__init__.py", line 1213, in _open
    return open_func(self.baseFilename, self.mode,
           ^^^^^^^^^^^^^^^^^^^^^^^^^^^^^^^^^^^^^^^
FileNotFoundError: [Errno 2] No such file or directory: '/Users/rehanahmad/Desktop/CISCO/du-soc-chat-svc-main/logs/django.log'

The above exception was the direct cause of the following exception:

Traceback (most recent call last):
  File "/Users/rehanahmad/.pyenv/versions/3.11.9/lib/python3.11/threading.py", line 1045, in _bootstrap_inner
    self.run()
  File "/Users/rehanahmad/.pyenv/versions/3.11.9/lib/python3.11/threading.py", line 982, in run
    self._target(*self._args, **self._kwargs)
  File "/Users/rehanahmad/.pyenv/versions/3.11.9/lib/python3.11/site-packages/django/utils/autoreload.py", line 64, in wrapper
    fn(*args, **kwargs)
  File "/Users/rehanahmad/.pyenv/versions/3.11.9/lib/python3.11/site-packages/django/core/management/commands/runserver.py", line 110, in inner_run
    autoreload.raise_last_exception()
  File "/Users/rehanahmad/.pyenv/versions/3.11.9/lib/python3.11/site-packages/django/utils/autoreload.py", line 87, in raise_last_exception
    raise _exception[1]
  File "/Users/rehanahmad/.pyenv/versions/3.11.9/lib/python3.11/site-packages/django/core/management/__init__.py", line 375, in execute
    autoreload.check_errors(django.setup)()
  File "/Users/rehanahmad/.pyenv/versions/3.11.9/lib/python3.11/site-packages/django/utils/autoreload.py", line 64, in wrapper
    fn(*args, **kwargs)
  File "/Users/rehanahmad/.pyenv/versions/3.11.9/lib/python3.11/site-packages/django/__init__.py", line 19, in setup
    configure_logging(settings.LOGGING_CONFIG, settings.LOGGING)
  File "/Users/rehanahmad/.pyenv/versions/3.11.9/lib/python3.11/site-packages/django/utils/log.py", line 75, in configure_logging
    logging_config_func(logging_settings)
  File "/Users/rehanahmad/.pyenv/versions/3.11.9/lib/python3.11/logging/config.py", line 823, in dictConfig
    dictConfigClass(config).configure()
  File "/Users/rehanahmad/.pyenv/versions/3.11.9/lib/python3.11/logging/config.py", line 580, in configure
    raise ValueError('Unable to configure handler '
ValueError: Unable to configure handler 'file'
/Users/rehanahmad/Desktop/CISCO/du-soc-chat-svc-main/chat_svc/settings/base.py changed, reloading.
INFO Watching for file changes with StatReloader
Exception in thread django-main-thread:
Traceback (most recent call last):
  File "/Users/rehanahmad/.pyenv/versions/3.11.9/lib/python3.11/threading.py", line 1045, in _bootstrap_inner
    self.run()
  File "/Users/rehanahmad/.pyenv/versions/3.11.9/lib/python3.11/threading.py", line 982, in run
    self._target(*self._args, **self._kwargs)
  File "/Users/rehanahmad/.pyenv/versions/3.11.9/lib/python3.11/site-packages/django/utils/autoreload.py", line 64, in wrapper
    fn(*args, **kwargs)
  File "/Users/rehanahmad/.pyenv/versions/3.11.9/lib/python3.11/site-packages/django/core/management/commands/runserver.py", line 110, in inner_run
    autoreload.raise_last_exception()
  File "/Users/rehanahmad/.pyenv/versions/3.11.9/lib/python3.11/site-packages/django/utils/autoreload.py", line 87, in raise_last_exception
    raise _exception[1]
  File "/Users/rehanahmad/.pyenv/versions/3.11.9/lib/python3.11/site-packages/django/core/management/__init__.py", line 375, in execute
    autoreload.check_errors(django.setup)()
  File "/Users/rehanahmad/.pyenv/versions/3.11.9/lib/python3.11/site-packages/django/utils/autoreload.py", line 64, in wrapper
    fn(*args, **kwargs)
  File "/Users/rehanahmad/.pyenv/versions/3.11.9/lib/python3.11/site-packages/django/__init__.py", line 24, in setup
    apps.populate(settings.INSTALLED_APPS)
  File "/Users/rehanahmad/.pyenv/versions/3.11.9/lib/python3.11/site-packages/django/apps/registry.py", line 91, in populate
    app_config = AppConfig.create(entry)
                 ^^^^^^^^^^^^^^^^^^^^^^^
  File "/Users/rehanahmad/.pyenv/versions/3.11.9/lib/python3.11/site-packages/django/apps/config.py", line 224, in create
    import_module(entry)
  File "/Users/rehanahmad/.pyenv/versions/3.11.9/lib/python3.11/importlib/__init__.py", line 126, in import_module
    return _bootstrap._gcd_import(name[level:], package, level)
           ^^^^^^^^^^^^^^^^^^^^^^^^^^^^^^^^^^^^^^^^^^^^^^^^^^^^
  File "<frozen importlib._bootstrap>", line 1204, in _gcd_import
  File "<frozen importlib._bootstrap>", line 1176, in _find_and_load
  File "<frozen importlib._bootstrap>", line 1140, in _find_and_load_unlocked
ModuleNotFoundError: No module named 'corsheaders'
INFO /Users/rehanahmad/Desktop/CISCO/du-soc-chat-svc-main/chat_svc/settings/base.py changed, reloading.
INFO Watching for file changes with StatReloader
Exception in thread django-main-thread:
Traceback (most recent call last):
  File "/Users/rehanahmad/.pyenv/versions/3.11.9/lib/python3.11/threading.py", line 1045, in _bootstrap_inner
    self.run()
  File "/Users/rehanahmad/.pyenv/versions/3.11.9/lib/python3.11/threading.py", line 982, in run
    self._target(*self._args, **self._kwargs)
  File "/Users/rehanahmad/.pyenv/versions/3.11.9/lib/python3.11/site-packages/django/utils/autoreload.py", line 64, in wrapper
    fn(*args, **kwargs)
  File "/Users/rehanahmad/.pyenv/versions/3.11.9/lib/python3.11/site-packages/django/core/management/commands/runserver.py", line 110, in inner_run
    autoreload.raise_last_exception()
  File "/Users/rehanahmad/.pyenv/versions/3.11.9/lib/python3.11/site-packages/django/utils/autoreload.py", line 87, in raise_last_exception
    raise _exception[1]
  File "/Users/rehanahmad/.pyenv/versions/3.11.9/lib/python3.11/site-packages/django/core/management/__init__.py", line 375, in execute
    autoreload.check_errors(django.setup)()
  File "/Users/rehanahmad/.pyenv/versions/3.11.9/lib/python3.11/site-packages/django/utils/autoreload.py", line 64, in wrapper
    fn(*args, **kwargs)
  File "/Users/rehanahmad/.pyenv/versions/3.11.9/lib/python3.11/site-packages/django/__init__.py", line 24, in setup
    apps.populate(settings.INSTALLED_APPS)
  File "/Users/rehanahmad/.pyenv/versions/3.11.9/lib/python3.11/site-packages/django/apps/registry.py", line 91, in populate
    app_config = AppConfig.create(entry)
                 ^^^^^^^^^^^^^^^^^^^^^^^
  File "/Users/rehanahmad/.pyenv/versions/3.11.9/lib/python3.11/site-packages/django/apps/config.py", line 224, in create
    import_module(entry)
  File "/Users/rehanahmad/.pyenv/versions/3.11.9/lib/python3.11/importlib/__init__.py", line 126, in import_module
    return _bootstrap._gcd_import(name[level:], package, level)
           ^^^^^^^^^^^^^^^^^^^^^^^^^^^^^^^^^^^^^^^^^^^^^^^^^^^^
  File "<frozen importlib._bootstrap>", line 1204, in _gcd_import
  File "<frozen importlib._bootstrap>", line 1176, in _find_and_load
  File "<frozen importlib._bootstrap>", line 1140, in _find_and_load_unlocked
ModuleNotFoundError: No module named 'corsheaders'
INFO /Users/rehanahmad/Desktop/CISCO/du-soc-chat-svc-main/chat_svc/settings/base.py changed, reloading.
INFO Watching for file changes with StatReloader
Exception in thread django-main-thread:
Traceback (most recent call last):
  File "/Users/rehanahmad/.pyenv/versions/3.11.9/lib/python3.11/threading.py", line 1045, in _bootstrap_inner
    self.run()
  File "/Users/rehanahmad/.pyenv/versions/3.11.9/lib/python3.11/threading.py", line 982, in run
    self._target(*self._args, **self._kwargs)
  File "/Users/rehanahmad/.pyenv/versions/3.11.9/lib/python3.11/site-packages/django/utils/autoreload.py", line 64, in wrapper
    fn(*args, **kwargs)
  File "/Users/rehanahmad/.pyenv/versions/3.11.9/lib/python3.11/site-packages/django/core/management/commands/runserver.py", line 110, in inner_run
    autoreload.raise_last_exception()
  File "/Users/rehanahmad/.pyenv/versions/3.11.9/lib/python3.11/site-packages/django/utils/autoreload.py", line 87, in raise_last_exception
    raise _exception[1]
  File "/Users/rehanahmad/.pyenv/versions/3.11.9/lib/python3.11/site-packages/django/core/management/__init__.py", line 375, in execute
    autoreload.check_errors(django.setup)()
  File "/Users/rehanahmad/.pyenv/versions/3.11.9/lib/python3.11/site-packages/django/utils/autoreload.py", line 64, in wrapper
    fn(*args, **kwargs)
  File "/Users/rehanahmad/.pyenv/versions/3.11.9/lib/python3.11/site-packages/django/__init__.py", line 24, in setup
    apps.populate(settings.INSTALLED_APPS)
  File "/Users/rehanahmad/.pyenv/versions/3.11.9/lib/python3.11/site-packages/django/apps/registry.py", line 91, in populate
    app_config = AppConfig.create(entry)
                 ^^^^^^^^^^^^^^^^^^^^^^^
  File "/Users/rehanahmad/.pyenv/versions/3.11.9/lib/python3.11/site-packages/django/apps/config.py", line 224, in create
    import_module(entry)
  File "/Users/rehanahmad/.pyenv/versions/3.11.9/lib/python3.11/importlib/__init__.py", line 126, in import_module
    return _bootstrap._gcd_import(name[level:], package, level)
           ^^^^^^^^^^^^^^^^^^^^^^^^^^^^^^^^^^^^^^^^^^^^^^^^^^^^
  File "<frozen importlib._bootstrap>", line 1204, in _gcd_import
  File "<frozen importlib._bootstrap>", line 1176, in _find_and_load
  File "<frozen importlib._bootstrap>", line 1140, in _find_and_load_unlocked
ModuleNotFoundError: No module named 'corsheaders'
INFO /Users/rehanahmad/Desktop/CISCO/du-soc-chat-svc-main/manage.py changed, reloading.
INFO Watching for file changes with StatReloader
Exception in thread django-main-thread:
Traceback (most recent call last):
  File "/Users/rehanahmad/.pyenv/versions/3.11.9/lib/python3.11/threading.py", line 1045, in _bootstrap_inner
    self.run()
  File "/Users/rehanahmad/.pyenv/versions/3.11.9/lib/python3.11/threading.py", line 982, in run
    self._target(*self._args, **self._kwargs)
  File "/Users/rehanahmad/.pyenv/versions/3.11.9/lib/python3.11/site-packages/django/utils/autoreload.py", line 64, in wrapper
    fn(*args, **kwargs)
  File "/Users/rehanahmad/.pyenv/versions/3.11.9/lib/python3.11/site-packages/django/core/management/commands/runserver.py", line 110, in inner_run
    autoreload.raise_last_exception()
  File "/Users/rehanahmad/.pyenv/versions/3.11.9/lib/python3.11/site-packages/django/utils/autoreload.py", line 87, in raise_last_exception
    raise _exception[1]
  File "/Users/rehanahmad/.pyenv/versions/3.11.9/lib/python3.11/site-packages/django/core/management/__init__.py", line 375, in execute
    autoreload.check_errors(django.setup)()
  File "/Users/rehanahmad/.pyenv/versions/3.11.9/lib/python3.11/site-packages/django/utils/autoreload.py", line 64, in wrapper
    fn(*args, **kwargs)
  File "/Users/rehanahmad/.pyenv/versions/3.11.9/lib/python3.11/site-packages/django/__init__.py", line 24, in setup
    apps.populate(settings.INSTALLED_APPS)
  File "/Users/rehanahmad/.pyenv/versions/3.11.9/lib/python3.11/site-packages/django/apps/registry.py", line 91, in populate
    app_config = AppConfig.create(entry)
                 ^^^^^^^^^^^^^^^^^^^^^^^
  File "/Users/rehanahmad/.pyenv/versions/3.11.9/lib/python3.11/site-packages/django/apps/config.py", line 224, in create
    import_module(entry)
  File "/Users/rehanahmad/.pyenv/versions/3.11.9/lib/python3.11/importlib/__init__.py", line 126, in import_module
    return _bootstrap._gcd_import(name[level:], package, level)
           ^^^^^^^^^^^^^^^^^^^^^^^^^^^^^^^^^^^^^^^^^^^^^^^^^^^^
  File "<frozen importlib._bootstrap>", line 1204, in _gcd_import
  File "<frozen importlib._bootstrap>", line 1176, in _find_and_load
  File "<frozen importlib._bootstrap>", line 1140, in _find_and_load_unlocked
ModuleNotFoundError: No module named 'corsheaders'
INFO /Users/rehanahmad/Desktop/CISCO/du-soc-chat-svc-main/manage.py changed, reloading.
INFO Watching for file changes with StatReloader
Exception in thread django-main-thread:
Traceback (most recent call last):
  File "/Users/rehanahmad/.pyenv/versions/3.11.9/lib/python3.11/threading.py", line 1045, in _bootstrap_inner
    self.run()
  File "/Users/rehanahmad/.pyenv/versions/3.11.9/lib/python3.11/threading.py", line 982, in run
    self._target(*self._args, **self._kwargs)
  File "/Users/rehanahmad/.pyenv/versions/3.11.9/lib/python3.11/site-packages/django/utils/autoreload.py", line 64, in wrapper
    fn(*args, **kwargs)
  File "/Users/rehanahmad/.pyenv/versions/3.11.9/lib/python3.11/site-packages/django/core/management/commands/runserver.py", line 110, in inner_run
    autoreload.raise_last_exception()
  File "/Users/rehanahmad/.pyenv/versions/3.11.9/lib/python3.11/site-packages/django/utils/autoreload.py", line 87, in raise_last_exception
    raise _exception[1]
  File "/Users/rehanahmad/.pyenv/versions/3.11.9/lib/python3.11/site-packages/django/core/management/__init__.py", line 375, in execute
    autoreload.check_errors(django.setup)()
  File "/Users/rehanahmad/.pyenv/versions/3.11.9/lib/python3.11/site-packages/django/utils/autoreload.py", line 64, in wrapper
    fn(*args, **kwargs)
  File "/Users/rehanahmad/.pyenv/versions/3.11.9/lib/python3.11/site-packages/django/__init__.py", line 24, in setup
    apps.populate(settings.INSTALLED_APPS)
  File "/Users/rehanahmad/.pyenv/versions/3.11.9/lib/python3.11/site-packages/django/apps/registry.py", line 91, in populate
    app_config = AppConfig.create(entry)
                 ^^^^^^^^^^^^^^^^^^^^^^^
  File "/Users/rehanahmad/.pyenv/versions/3.11.9/lib/python3.11/site-packages/django/apps/config.py", line 224, in create
    import_module(entry)
  File "/Users/rehanahmad/.pyenv/versions/3.11.9/lib/python3.11/importlib/__init__.py", line 126, in import_module
    return _bootstrap._gcd_import(name[level:], package, level)
           ^^^^^^^^^^^^^^^^^^^^^^^^^^^^^^^^^^^^^^^^^^^^^^^^^^^^
  File "<frozen importlib._bootstrap>", line 1204, in _gcd_import
  File "<frozen importlib._bootstrap>", line 1176, in _find_and_load
  File "<frozen importlib._bootstrap>", line 1140, in _find_and_load_unlocked
ModuleNotFoundError: No module named 'corsheaders'
